Workbook

Sheet Copper
B3: LME DAILY OFFICIAL AND SETTLEMENT PRICES
B4: LME COPPER $USD/Tonne
B6: 44013
C7: CASH | F7: 3-MONTHS | I7: DECEMBER 1 | L7: DECEMBER 2 | O7: DECEMBER 3 | R7: SETTLEMENT | S7: Exchange Rate | V7: Sterling Equivalents | X7: Euro Equivalents | Y7: 3MStg/$
C8: BUYER | D8: SELLER | E8: Mean | F8: BUYER | G8: SELLER | H8: Mean | I8: BUYER | J8: SELLER | K8: Mean | L8: BUYER | M8: SELLER | N8: Mean | O8: BUYER | P8: SELLER | Q8: Mean | S8: Stg/$ | T8: EURO | U8: Yen | V8: Cash Seller's | W8: 3mths Seller's | X8: Cash Seller's | Y8: 3MStg/$
B9: 44013 | C9: 6016.5 | D9: 6016.5 | E9: =AVERAGE(C9:D9) -> 6016.5 | F9: 6023.5 | G9: 6023.5 | H9: =AVERAGE(F9:G9) -> 6023.5 | I9: 6060.5 | J9: 6060.5 | K9: =AVERAGE(I9:J9) -> 6060.5 | L9: 6099.5 | M9: 6099.5 | N9: =AVERAGE(L9:M9) -> 6099.5 | O9: 6150.5 | P9: 6150.5 | Q9: =AVERAGE(O9:P9) -> 6150.5 | R9: 6016.5 | S9: 1.239 | T9: 1.1204 | U9: 107.46 | V9: 4855.93 | W9: 4858.84 | X9: =R9/T9 -> 5369.9572 | Y9: 1.2397
B10: 44014 | C10: 6080 | D10: 6080 | E10: =AVERAGE(C10:D10) -> 6080 | F10: 6083 | G10: 6083 | H10: =AVERAGE(F10:G10) -> 6083 | I10: 6118 | J10: 6118 | K10: =AVERAGE(I10:J10) -> 6118 | L10: 6156 | M10: 6156 | N10: =AVERAGE(L10:M10) -> 6156 | O10: 6206 | P10: 6206 | Q10: =AVERAGE(O10:P10) -> 6206 | R10: 6080 | S10: 1.2519 | T10: 1.1287 | U10: 107.46 | V10: 4856.62 | W10: 4856.3 | X10: =R10/T10 -> 5386.7281 | Y10: 1.2526
B11: 44015 | C11: 6022.5 | D11: 6022.5 | E11: =AVERAGE(C11:D11) -> 6022.5 | F11: 6021 | G11: 6021 | H11: =AVERAGE(F11:G11) -> 6021 | I11: 6056 | J11: 6056 | K11: =AVERAGE(I11:J11) -> 6056 | L11: 6094 | M11: 6094 | N11: =AVERAGE(L11:M11) -> 6094 | O11: 6144 | P11: 6144 | Q11: =AVERAGE(O11:P11) -> 6144 | R11: 6022.5 | S11: 1.2454 | T11: 1.1224 | U11: 107.53 | V11: 4835.8 | W11: 4832.26 | X11: =R11/T11 -> 5365.7341 | Y11: 1.246
B12: 44018 | C12: 6112 | D12: 6112 | E12: =AVERAGE(C12:D12) -> 6112 | F12: 6105 | G12: 6105 | H12: =AVERAGE(F12:G12) -> 6105 | I12: 6128 | J12: 6128 | K12: =AVERAGE(I12:J12) -> 6128 | L12: 6160 | M12: 6160 | N12: =AVERAGE(L12:M12) -> 6160 | O12: 6210 | P12: 6210 | Q12: =AVERAGE(O12:P12) -> 6210 | R12: 6112 | S12: 1.251 | T12: 1.1319 | U12: 107.53 | V12: 4885.69 | W12: 4877.37 | X12: =R12/T12 -> 5399.7703 | Y12: 1.2517
B13: 44019 | C13: 6086 | D13: 6086 | E13: =AVERAGE(C13:D13) -> 6086 | F13: 6089 | G13: 6089 | H13: =AVERAGE(F13:G13) -> 6089 | I13: 6107.5 | J13: 6107.5 | K13: =AVERAGE(I13:J13) -> 6107.5 | L13: 6137.5 | M13: 6137.5 | N13: =AVERAGE(L13:M13) -> 6137.5 | O13: 6182.5 | P13: 6182.5 | Q13: =AVERAGE(O13:P13) -> 6182.5 | R13: 6086 | S13: 1.2519 | T13: 1.1291 | U13: 107.72 | V13: 4861.41 | W13: 4861.09 | X13: =R13/T13 -> 5390.1337 | Y13: 1.2526
B14: 44020 | C14: 6194 | D14: 6194 | E14: =AVERAGE(C14:D14) -> 6194 | F14: 6197.5 | G14: 6197.5 | H14: =AVERAGE(F14:G14) -> 6197.5 | I14: 6207.5 | J14: 6207.5 | K14: =AVERAGE(I14:J14) -> 6207.5 | L14: 6235.5 | M14: 6235.5 | N14: =AVERAGE(L14:M14) -> 6235.5 | O14: 6280.5 | P14: 6280.5 | Q14: =AVERAGE(O14:P14) -> 6280.5 | R14: 6194 | S14: 1.2559 | T14: 1.129 | U14: 107.52 | V14: 4931.92 | W14: 4931.96 | X14: =R14/T14 -> 5486.271 | Y14: 1.2566
B15: 44021 | C15: 6339.5 | D15: 6339.5 | E15: =AVERAGE(C15:D15) -> 6339.5 | F15: 6339.5 | G15: 6339.5 | H15: =AVERAGE(F15:G15) -> 6339.5 | I15: 6337.5 | J15: 6337.5 | K15: =AVERAGE(I15:J15) -> 6337.5 | L15: 6362.5 | M15: 6362.5 | N15: =AVERAGE(L15:M15) -> 6362.5 | O15: 6407.5 | P15: 6407.5 | Q15: =AVERAGE(O15:P15) -> 6407.5 | R15: 6339.5 | S15: 1.2652 | T15: 1.1343 | U15: 107.29 | V15: 5010.67 | W15: 5008.3 | X15: =R15/T15 -> 5588.9095 | Y15: 1.2658
B16: 44022 | C16: 6322.5 | D16: 6322.5 | E16: =AVERAGE(C16:D16) -> 6322.5 | F16: 6320 | G16: 6320 | H16: =AVERAGE(F16:G16) -> 6320 | I16: 6326 | J16: 6326 | K16: =AVERAGE(I16:J16) -> 6326 | L16: 6351.5 | M16: 6351.5 | N16: =AVERAGE(L16:M16) -> 6351.5 | O16: 6396 | P16: 6396 | Q16: =AVERAGE(O16:P16) -> 6396 | R16: 6322.5 | S16: 1.2599 | T16: 1.1286 | U16: 106.86 | V16: 5018.26 | W16: 5013.49 | X16: =R16/T16 -> 5602.0734 | Y16: 1.2606
B17: 44025 | C17: 6545 | D17: 6545 | E17: =AVERAGE(C17:D17) -> 6545 | F17: 6537 | G17: 6537 | H17: =AVERAGE(F17:G17) -> 6537 | I17: 6514 | J17: 6514 | K17: =AVERAGE(I17:J17) -> 6514 | L17: 6529 | M17: 6529 | N17: =AVERAGE(L17:M17) -> 6529 | O17: 6564 | P17: 6564 | Q17: =AVERAGE(O17:P17) -> 6564 | R17: 6545 | S17: 1.2604 | T17: 1.1335 | U17: 107.1 | V17: 5192.8 | W17: 5183.16 | X17: =R17/T17 -> 5774.1509 | Y17: 1.2612
B18: 44026 | C18: 6489.5 | D18: 6489.5 | E18: =AVERAGE(C18:D18) -> 6489.5 | F18: 6491 | G18: 6491 | H18: =AVERAGE(F18:G18) -> 6491 | I18: 6474 | J18: 6474 | K18: =AVERAGE(I18:J18) -> 6474 | L18: 6489 | M18: 6489 | N18: =AVERAGE(L18:M18) -> 6489 | O18: 6524 | P18: 6524 | Q18: =AVERAGE(O18:P18) -> 6524 | R18: 6489.5 | S18: 1.253 | T18: 1.1378 | U18: 107.37 | V18: 5179.17 | W18: 5177.47 | X18: =R18/T18 -> 5703.5507 | Y18: 1.2537
B19: 44027 | C19: 6507 | D19: 6507 | E19: =AVERAGE(C19:D19) -> 6507 | F19: 6510 | G19: 6510 | H19: =AVERAGE(F19:G19) -> 6510 | I19: 6504.5 | J19: 6504.5 | K19: =AVERAGE(I19:J19) -> 6504.5 | L19: 6520.5 | M19: 6520.5 | N19: =AVERAGE(L19:M19) -> 6520.5 | O19: 6555.5 | P19: 6555.5 | Q19: =AVERAGE(O19:P19) -> 6555.5 | R19: 6507 | S19: 1.2632 | T19: 1.1439 | U19: 106.9 | V19: 5151.2 | W19: 5150.72 | X19: =R19/T19 -> 5688.4343 | Y19: 1.2639
B20: 44028 | C20: 6385 | D20: 6385 | E20: =AVERAGE(C20:D20) -> 6385 | F20: 6384 | G20: 6384 | H20: =AVERAGE(F20:G20) -> 6384 | I20: 6377 | J20: 6377 | K20: =AVERAGE(I20:J20) -> 6377 | L20: 6394.5 | M20: 6394.5 | N20: =AVERAGE(L20:M20) -> 6394.5 | O20: 6429.5 | P20: 6429.5 | Q20: =AVERAGE(O20:P20) -> 6429.5 | R20: 6385 | S20: 1.2555 | T20: 1.1413 | U20: 107.09 | V20: 5085.62 | W20: 5082.4 | X20: =R20/T20 -> 5594.4975 | Y20: 1.2561
... B31: 44043 | C31: 6446.5 | D31: 6446.5 | E31: =AVERAGE(C31:D31) -> 6446.5 | F31: 6439.5 | G31: 6439.5 | H31: =AVERAGE(F31:G31) -> 6439.5 | I31: 6429.5 | J31: 6429.5 | K31: =AVERAGE(I31:J31) -> 6429.5 | L31: 6445 | M31: 6445 | N31: =AVERAGE(L31:M31) -> 6445 | O31: 6470 | P31: 6470 | Q31: =AVERAGE(O31:P31) -> 6470 | R31: 6446.5 | S31: 1.3142 | T31: 1.1841 | U31: 104.91 | V31: 4905.27 | W31: 4897.7 | X31: =R31/T31 -> 5444.2192 | Y31: 1.3148
B32: Average | C32: =ROUND(AVERAGE(C9:C31),2) -> 6353.76 | D32: =ROUND(AVERAGE(D9:D31),2) -> 6353.76 | E32: =ROUND(AVERAGE(C32:D32),2) -> 6353.76 | F32: =ROUND(AVERAGE(F9:F31),2) -> 6348.59 | G32: =ROUND(AVERAGE(G9:G31),2) -> 6348.59 | H32: =ROUND(AVERAGE(F32:G32),2) -> 6348.59 | I32: =ROUND(AVERAGE(I9:I31),2) -> 6345.24 | J32: =ROUND(AVERAGE(J9:J31),2) -> 6345.24 | K32: =ROUND(AVERAGE(I32:J32),2) -> 6345.24 | L32: =ROUND(AVERAGE(L9:L31),2) -> 6364.7 | M32: =ROUND(AVERAGE(M9:M31),2) -> 6364.7 | N32: =ROUND(AVERAGE(L32:M32),2) -> 6364.7 | O32: =ROUND(AVERAGE(O9:O31),2) -> 6400.78 | P32: =ROUND(AVERAGE(P9:P31),2) -> 6400.78 | Q32: =ROUND(AVERAGE(O32:P32),2) -> 6400.78 | R32: =ROUND(AVERAGE(R9:R31),2) -> 6353.76 | S32: =ROUND(AVERAGE(S9:S31),4) -> 1.267 | T32: =ROUND(AVERAGE(T9:T31),4) -> 1.1462 | U32: =ROUND(AVERAGE(U9:U31),2) -> 106.77 | V32: =AVERAGE(V9:V31) -> 5014.9013 | W32: =AVERAGE(W9:W31) -> 5008.2552 | X32: =AVERAGE(X9:X31) -> 5543.2215 | Y32: =AVERAGE(Y9:Y31) -> 1.2676261
B33: High | C33: =MAX(C9:C31) -> 6545 | D33: =MAX(D9:D31) -> 6545 | E33: =MAX(E9:E31) -> 6545 | F33: =MAX(F9:F31) -> 6537 | G33: =MAX(G9:G31) -> 6537 | H33: =MAX(H9:H31) -> 6537 | I33: =MAX(I9:I31) -> 6514 | J33: =MAX(J9:J31) -> 6514 | ... Y33: =MAX(Y9:Y31) -> 1.3148
B34: Low | C34: =MIN(C9:C31) -> 6016.5 | D34: =MIN(D9:D31) -> 6016.5 | E34: =MIN(E9:E31) -> 6016.5 | F34: =MIN(F9:F31) -> 6021 | G34: =MIN(G9:G31) -> 6021 | H34: =MIN(H9:H31) -> 6021 | I34: =MIN(I9:I31) -> 6056 | J34: =MIN(J9:J31) -> 6056 | ... Y34: =MIN(Y9:Y31) -> 1.2397
B36: Neither the LME nor any of its directors, officers or employees shall, except in the case of fraud or wilful neglect, be under any liability whatsoever either in
B37: contract or in tort in respect of any act or omission (including negligence) in relation to the preparation or publication of the data contained in the report

Sheet Aluminium Alloy
B3: LME DAILY OFFICIAL AND SETTLEMENT PRICES
B4: LME ALUMINIUM ALLOY $USD/Tonne
B6: 44013
C7: CASH | F7: 3-MONTHS | I7: DECEMBER 1 | L7: SETTLEMENT | M7: Exchange Rate | P7: Sterling Equivalents | R7: Euro Equivalents | S7: 3MStg/$
C8: BUYER | D8: SELLER | E8: Mean | F8: BUYER | G8: SELLER | H8: Mean | I8: BUYER | J8: SELLER | K8: Mean | M8: Stg/$ | N8: EURO | O8: Yen | P8: Cash Seller's | Q8: 3mths Seller's | R8: Cash Seller's | S8: 3MStg/$
B9: 44013 | C9: 1215 | D9: 1215 | E9: =AVERAGE(C9:D9) -> 1215 | F9: 1210 | G9: 1210 | H9: =AVERAGE(F9:G9) -> 1210 | I9: 1209 | J9: 1209 | K9: =AVERAGE(I9:J9) -> 1209 | L9: 1215 | M9: 1.239 | N9: 1.1204 | O9: 107.46 | P9: 980.63 | Q9: 976.04 | R9: =L9/N9 -> 1084.4341 | S9: 1.2397
B10: 44014 | C10: 1215 | D10: 1215 | E10: =AVERAGE(C10:D10) -> 1215 | F10: 1210 | G10: 1210 | H10: =AVERAGE(F10:G10) -> 1210 | I10: 1209 | J10: 1209 | K10: =AVERAGE(I10:J10) -> 1209 | L10: 1215 | M10: 1.2519 | N10: 1.1287 | O10: 107.46 | P10: 970.52 | Q10: 965.99 | R10: =L10/N10 -> 1076.4596 | S10: 1.2526
B11: 44015 | C11: 1190 | D11: 1190 | E11: =AVERAGE(C11:D11) -> 1190 | F11: 1200 | G11: 1200 | H11: =AVERAGE(F11:G11) -> 1200 | I11: 1199 | J11: 1199 | K11: =AVERAGE(I11:J11) -> 1199 | L11: 1190 | M11: 1.2454 | N11: 1.1224 | O11: 107.53 | P11: 955.52 | Q11: 963.08 | R11: =L11/N11 -> 1060.2281 | S11: 1.246
B12: 44018 | C12: 1220 | D12: 1220 | E12: =AVERAGE(C12:D12) -> 1220 | F12: 1220 | G12: 1220 | H12: =AVERAGE(F12:G12) -> 1220 | I12: 1219 | J12: 1219 | K12: =AVERAGE(I12:J12) -> 1219 | L12: 1220 | M12: 1.251 | N12: 1.1319 | O12: 107.53 | P12: 975.22 | Q12: 974.67 | R12: =L12/N12 -> 1077.8337 | S12: 1.2517
B13: 44019 | C13: 1180 | D13: 1180 | E13: =AVERAGE(C13:D13) -> 1180 | F13: 1180 | G13: 1180 | H13: =AVERAGE(F13:G13) -> 1180 | I13: 1179 | J13: 1179 | K13: =AVERAGE(I13:J13) -> 1179 | L13: 1180 | M13: 1.2519 | N13: 1.1291 | O13: 107.72 | P13: 942.57 | Q13: 942.04 | R13: =L13/N13 -> 1045.0802 | S13: 1.2526
B14: 44020 | C14: 1150 | D14: 1150 | E14: =AVERAGE(C14:D14) -> 1150 | F14: 1150 | G14: 1150 | H14: =AVERAGE(F14:G14) -> 1150 | I14: 1149 | J14: 1149 | K14: =AVERAGE(I14:J14) -> 1149 | L14: 1150 | M14: 1.2559 | N14: 1.129 | O14: 107.52 | P14: 915.68 | Q14: 915.17 | R14: =L14/N14 -> 1018.6005 | S14: 1.2566
B15: 44021 | C15: 1180.5 | D15: 1180.5 | E15: =AVERAGE(C15:D15) -> 1180.5 | F15: 1180 | G15: 1180 | H15: =AVERAGE(F15:G15) -> 1180 | I15: 1177.5 | J15: 1177.5 | K15: =AVERAGE(I15:J15) -> 1177.5 | L15: 1180.5 | M15: 1.2652 | N15: 1.1343 | O15: 107.29 | P15: 933.05 | Q15: 932.22 | R15: =L15/N15 -> 1040.73 | S15: 1.2658
B16: 44022 | C16: 1205 | D16: 1205 | E16: =AVERAGE(C16:D16) -> 1205 | F16: 1205 | G16: 1205 | H16: =AVERAGE(F16:G16) -> 1205 | I16: 1202 | J16: 1202 | K16: =AVERAGE(I16:J16) -> 1202 | L16: 1205 | M16: 1.2599 | N16: 1.1286 | O16: 106.86 | P16: 956.43 | Q16: 955.89 | R16: =L16/N16 -> 1067.6945 | S16: 1.2606
B17: 44025 | C17: 1240 | D17: 1240 | E17: =AVERAGE(C17:D17) -> 1240 | F17: 1240 | G17: 1240 | H17: =AVERAGE(F17:G17) -> 1240 | I17: 1237 | J17: 1237 | K17: =AVERAGE(I17:J17) -> 1237 | L17: 1240 | M17: 1.2604 | N17: 1.1335 | O17: 107.1 | P17: 983.81 | Q17: 983.19 | R17: =L17/N17 -> 1093.9568 | S17: 1.2612
B18: 44026 | C18: 1240 | D18: 1240 | E18: =AVERAGE(C18:D18) -> 1240 | F18: 1240 | G18: 1240 | H18: =AVERAGE(F18:G18) -> 1240 | I18: 1237 | J18: 1237 | K18: =AVERAGE(I18:J18) -> 1237 | L18: 1240 | M18: 1.253 | N18: 1.1378 | O18: 107.37 | P18: 989.62 | Q18: 989.07 | R18: =L18/N18 -> 1089.8225 | S18: 1.2537
B19: 44027 | C19: 1260 | D19: 1260 | E19: =AVERAGE(C19:D19) -> 1260 | F19: 1260 | G19: 1260 | H19: =AVERAGE(F19:G19) -> 1260 | I19: 1257 | J19: 1257 | K19: =AVERAGE(I19:J19) -> 1257 | L19: 1260 | M19: 1.2632 | N19: 1.1439 | O19: 106.9 | P19: 997.47 | Q19: 996.91 | R19: =L19/N19 -> 1101.4949 | S19: 1.2639
B20: 44028 | C20: 1260 | D20: 1260 | E20: =AVERAGE(C20:D20) -> 1260 | F20: 1260 | G20: 1260 | H20: =AVERAGE(F20:G20) -> 1260 | I20: 1256 | J20: 1256 | K20: =AVERAGE(I20:J20) -> 1256 | L20: 1260 | M20: 1.2555 | N20: 1.1413 | O20: 107.09 | P20: 1003.58 | Q20: 1003.1 | R20: =L20/N20 -> 1104.0042 | S20: 1.2561
... B31: 44043 | C31: 1318.5 | D31: 1318.5 | E31: =AVERAGE(C31:D31) -> 1318.5 | F31: 1325 | G31: 1325 | H31: =AVERAGE(F31:G31) -> 1325 | I31: 1336 | J31: 1336 | K31: =AVERAGE(I31:J31) -> 1336 | L31: 1318.5 | M31: 1.3142 | N31: 1.1841 | O31: 104.91 | P31: 1003.27 | Q31: 1007.76 | R31: =L31/N31 -> 1113.5039 | S31: 1.3148
B32: Average | C32: =ROUND(AVERAGE(C9:C31),2) -> 1249.76 | D32: =ROUND(AVERAGE(D9:D31),2) -> 1249.76 | E32: =ROUND(AVERAGE(C32:D32),2) -> 1249.76 | F32: =ROUND(AVERAGE(F9:F31),2) -> 1251.74 | G32: =ROUND(AVERAGE(G9:G31),2) -> 1251.74 | H32: =ROUND(AVERAGE(F32:G32),2) -> 1251.74 | I32: =ROUND(AVERAGE(I9:I31),2) -> 1247.04 | J32: =ROUND(AVERAGE(J9:J31),2) -> 1247.04 | K32: =ROUND(AVERAGE(I32:J32),2) -> 1247.04 | L32: =ROUND(AVERAGE(L9:L31),2) -> 1249.76 | M32: =ROUND(AVERAGE(M9:M31),4) -> 1.267 | N32: =ROUND(AVERAGE(N9:N31),4) -> 1.1462 | O32: =ROUND(AVERAGE(O9:O31),2) -> 106.77 | P32: =AVERAGE(P9:P31) -> 986.21217 | Q32: =AVERAGE(Q9:Q31) -> 987.22435 | R32: =AVERAGE(R9:R31) -> 1090.0273 | S32: =AVERAGE(S9:S31) -> 1.2676261
B33: High | C33: =MAX(C9:C31) -> 1318.5 | D33: =MAX(D9:D31) -> 1318.5 | E33: =MAX(E9:E31) -> 1318.5 | F33: =MAX(F9:F31) -> 1325 | G33: =MAX(G9:G31) -> 1325 | H33: =MAX(H9:H31) -> 1325 | I33: =MAX(I9:I31) -> 1336 | J33: =MAX(J9:J31) -> 1336 | ... S33: =MAX(S9:S31) -> 1.3148
B34: Low | C34: =MIN(C9:C31) -> 1150 | D34: =MIN(D9:D31) -> 1150 | E34: =MIN(E9:E31) -> 1150 | F34: =MIN(F9:F31) -> 1150 | G34: =MIN(G9:G31) -> 1150 | H34: =MIN(H9:H31) -> 1150 | I34: =MIN(I9:I31) -> 1149 | J34: =MIN(J9:J31) -> 1149 | ... S34: =MIN(S9:S31) -> 1.2397
B36: Neither the LME nor any of its directors, officers or employees shall, except in the case of fraud or wilful neglect, be under any liability whatsoever either in
B37: contract or in tort in respect of any act or omission (including negligence) in relation to the preparation or publication of the data contained in the report

Sheet NA Alloy
B3: LME DAILY OFFICIAL AND SETTLEMENT PRICES
B4: LME NA ALLOY $USD/Tonne
B6: 44013
C7: CASH | F7: 3-MONTHS | I7: DECEMBER 1 | L7: SETTLEMENT | M7: Exchange Rate | P7: Sterling Equivalents | R7: Euro Equivalents | S7: 3MStg/$
C8: BUYER | D8: SELLER | E8: Mean | F8: BUYER | G8: SELLER | H8: Mean | I8: BUYER | J8: SELLER | K8: Mean | M8: Stg/$ | N8: EURO | O8: Yen | P8: Cash Seller's | Q8: 3mths Seller's | R8: Cash Seller's | S8: 3MStg/$
B9: 44013 | C9: 1220 | D9: 1220 | E9: =AVERAGE(C9:D9) -> 1220 | F9: 1220 | G9: 1220 | H9: =AVERAGE(F9:G9) -> 1220 | I9: 1235.5 | J9: 1235.5 | K9: =AVERAGE(I9:J9) -> 1235.5 | L9: 1220 | M9: 1.239 | N9: 1.1204 | O9: 107.46 | P9: 984.67 | Q9: 984.11 | R9: =L9/N9 -> 1088.8968 | S9: 1.2397
B10: 44014 | C10: 1225 | D10: 1225 | E10: =AVERAGE(C10:D10) -> 1225 | F10: 1225 | G10: 1225 | H10: =AVERAGE(F10:G10) -> 1225 | I10: 1240 | J10: 1240 | K10: =AVERAGE(I10:J10) -> 1240 | L10: 1225 | M10: 1.2519 | N10: 1.1287 | O10: 107.46 | P10: 978.51 | Q10: 977.97 | R10: =L10/N10 -> 1085.3194 | S10: 1.2526
B11: 44015 | C11: 1225 | D11: 1225 | E11: =AVERAGE(C11:D11) -> 1225 | F11: 1225 | G11: 1225 | H11: =AVERAGE(F11:G11) -> 1225 | I11: 1240 | J11: 1240 | K11: =AVERAGE(I11:J11) -> 1240 | L11: 1225 | M11: 1.2454 | N11: 1.1224 | O11: 107.53 | P11: 983.62 | Q11: 983.15 | R11: =L11/N11 -> 1091.4113 | S11: 1.246
B12: 44018 | C12: 1225 | D12: 1225 | E12: =AVERAGE(C12:D12) -> 1225 | F12: 1225 | G12: 1225 | H12: =AVERAGE(F12:G12) -> 1225 | I12: 1239.5 | J12: 1239.5 | K12: =AVERAGE(I12:J12) -> 1239.5 | L12: 1225 | M12: 1.251 | N12: 1.1319 | O12: 107.53 | P12: 979.22 | Q12: 978.67 | R12: =L12/N12 -> 1082.2511 | S12: 1.2517
B13: 44019 | C13: 1224.5 | D13: 1224.5 | E13: =AVERAGE(C13:D13) -> 1224.5 | F13: 1225 | G13: 1225 | H13: =AVERAGE(F13:G13) -> 1225 | I13: 1239.5 | J13: 1239.5 | K13: =AVERAGE(I13:J13) -> 1239.5 | L13: 1224.5 | M13: 1.2519 | N13: 1.1291 | O13: 107.72 | P13: 978.11 | Q13: 977.97 | R13: =L13/N13 -> 1084.4921 | S13: 1.2526
B14: 44020 | C14: 1234.5 | D14: 1234.5 | E14: =AVERAGE(C14:D14) -> 1234.5 | F14: 1235 | G14: 1235 | H14: =AVERAGE(F14:G14) -> 1235 | I14: 1249.5 | J14: 1249.5 | K14: =AVERAGE(I14:J14) -> 1249.5 | L14: 1234.5 | M14: 1.2559 | N14: 1.129 | O14: 107.52 | P14: 982.96 | Q14: 982.81 | R14: =L14/N14 -> 1093.4455 | S14: 1.2566
B15: 44021 | C15: 1264.5 | D15: 1264.5 | E15: =AVERAGE(C15:D15) -> 1264.5 | F15: 1265 | G15: 1265 | H15: =AVERAGE(F15:G15) -> 1265 | I15: 1279.5 | J15: 1279.5 | K15: =AVERAGE(I15:J15) -> 1279.5 | L15: 1264.5 | M15: 1.2652 | N15: 1.1343 | O15: 107.29 | P15: 999.45 | Q15: 999.37 | R15: =L15/N15 -> 1114.7844 | S15: 1.2658
B16: 44022 | C16: 1275 | D16: 1275 | E16: =AVERAGE(C16:D16) -> 1275 | F16: 1275.5 | G16: 1275.5 | H16: =AVERAGE(F16:G16) -> 1275.5 | I16: 1290 | J16: 1290 | K16: =AVERAGE(I16:J16) -> 1290 | L16: 1275 | M16: 1.2599 | N16: 1.1286 | O16: 106.86 | P16: 1011.99 | Q16: 1011.82 | R16: =L16/N16 -> 1129.7182 | S16: 1.2606
B17: 44025 | C17: 1289 | D17: 1289 | E17: =AVERAGE(C17:D17) -> 1289 | F17: 1290 | G17: 1290 | H17: =AVERAGE(F17:G17) -> 1290 | I17: 1304 | J17: 1304 | K17: =AVERAGE(I17:J17) -> 1304 | L17: 1289 | M17: 1.2604 | N17: 1.1335 | O17: 107.1 | P17: 1022.69 | Q17: 1022.84 | R17: =L17/N17 -> 1137.1857 | S17: 1.2612
B18: 44026 | C18: 1289 | D18: 1289 | E18: =AVERAGE(C18:D18) -> 1289 | F18: 1290 | G18: 1290 | H18: =AVERAGE(F18:G18) -> 1290 | I18: 1304 | J18: 1304 | K18: =AVERAGE(I18:J18) -> 1304 | L18: 1289 | M18: 1.253 | N18: 1.1378 | O18: 107.37 | P18: 1028.73 | Q18: 1028.95 | R18: =L18/N18 -> 1132.888 | S18: 1.2537
B19: 44027 | C19: 1309 | D19: 1309 | E19: =AVERAGE(C19:D19) -> 1309 | F19: 1310 | G19: 1310 | H19: =AVERAGE(F19:G19) -> 1310 | I19: 1324 | J19: 1324 | K19: =AVERAGE(I19:J19) -> 1324 | L19: 1309 | M19: 1.2632 | N19: 1.1439 | O19: 106.9 | P19: 1036.26 | Q19: 1036.47 | R19: =L19/N19 -> 1144.3308 | S19: 1.2639
B20: 44028 | C20: 1280 | D20: 1280 | E20: =AVERAGE(C20:D20) -> 1280 | F20: 1281.5 | G20: 1281.5 | H20: =AVERAGE(F20:G20) -> 1281.5 | I20: 1295 | J20: 1295 | K20: =AVERAGE(I20:J20) -> 1295 | L20: 1280 | M20: 1.2555 | N20: 1.1413 | O20: 107.09 | P20: 1019.51 | Q20: 1020.22 | R20: =L20/N20 -> 1121.5281 | S20: 1.2561
... B31: 44043 | C31: 1305.5 | D31: 1305.5 | E31: =AVERAGE(C31:D31) -> 1305.5 | F31: 1310 | G31: 1310 | H31: =AVERAGE(F31:G31) -> 1310 | I31: 1338 | J31: 1338 | K31: =AVERAGE(I31:J31) -> 1338 | L31: 1305.5 | M31: 1.3142 | N31: 1.1841 | O31: 104.91 | P31: 993.38 | Q31: 996.35 | R31: =L31/N31 -> 1102.5251 | S31: 1.3148
B32: Average | C32: =ROUND(AVERAGE(C9:C31),2) -> 1265.26 | D32: =ROUND(AVERAGE(D9:D31),2) -> 1265.26 | E32: =ROUND(AVERAGE(C32:D32),2) -> 1265.26 | F32: =ROUND(AVERAGE(F9:F31),2) -> 1268.96 | G32: =ROUND(AVERAGE(G9:G31),2) -> 1268.96 | H32: =ROUND(AVERAGE(F32:G32),2) -> 1268.96 | I32: =ROUND(AVERAGE(I9:I31),2) -> 1286.04 | J32: =ROUND(AVERAGE(J9:J31),2) -> 1286.04 | K32: =ROUND(AVERAGE(I32:J32),2) -> 1286.04 | L32: =ROUND(AVERAGE(L9:L31),2) -> 1265.26 | M32: =ROUND(AVERAGE(M9:M31),4) -> 1.267 | N32: =ROUND(AVERAGE(N9:N31),4) -> 1.1462 | O32: =ROUND(AVERAGE(O9:O31),2) -> 106.77 | P32: =AVERAGE(P9:P31) -> 998.70783 | Q32: =AVERAGE(Q9:Q31) -> 1001.0483 | R32: =AVERAGE(R9:R31) -> 1103.9488 | S32: =AVERAGE(S9:S31) -> 1.2676261
B33: High | C33: =MAX(C9:C31) -> 1309 | D33: =MAX(D9:D31) -> 1309 | E33: =MAX(E9:E31) -> 1309 | F33: =MAX(F9:F31) -> 1310 | G33: =MAX(G9:G31) -> 1310 | H33: =MAX(H9:H31) -> 1310 | I33: =MAX(I9:I31) -> 1338 | J33: =MAX(J9:J31) -> 1338 | ... S33: =MAX(S9:S31) -> 1.3148
B34: Low | C34: =MIN(C9:C31) -> 1220 | D34: =MIN(D9:D31) -> 1220 | E34: =MIN(E9:E31) -> 1220 | F34: =MIN(F9:F31) -> 1220 | G34: =MIN(G9:G31) -> 1220 | H34: =MIN(H9:H31) -> 1220 | I34: =MIN(I9:I31) -> 1235.5 | J34: =MIN(J9:J31) -> 1235.5 | ... S34: =MIN(S9:S31) -> 1.2397
B36: Neither the LME nor any of its directors, officers or employees shall, except in the case of fraud or wilful neglect, be under any liability whatsoever either in
B37: contract or in tort in respect of any act or omission (including negligence) in relation to the preparation or publication of the data contained in the report

Sheet Primary Aluminium
B3: LME DAILY OFFICIAL AND SETTLEMENT PRICES
B4: LME PRIMARY ALUMINIUM $USD/Tonne
B6: 44013
C7: CASH | F7: 3-MONTHS | I7: DECEMBER 1 | L7: DECEMBER 2 | O7: DECEMBER 3 | R7: SETTLEMENT | S7: Exchange Rate | V7: Sterling Equivalents | X7: Euro Equivalents | Y7: 3MStg/$
C8: BUYER | D8: SELLER | E8: Mean | F8: BUYER | G8: SELLER | H8: Mean | I8: BUYER | J8: SELLER | K8: Mean | L8: BUYER | M8: SELLER | N8: Mean | O8: BUYER | P8: SELLER | Q8: Mean | S8: Stg/$ | T8: EURO | U8: Yen | V8: Cash Seller's | W8: 3mths Seller's | X8: Cash Seller's | Y8: 3MStg/$
B9: 44013 | C9: 1593.5 | D9: 1593.5 | E9: =AVERAGE(C9:D9) -> 1593.5 | F9: 1614 | G9: 1614 | H9: =AVERAGE(F9:G9) -> 1614 | I9: 1713 | J9: 1713 | K9: =AVERAGE(I9:J9) -> 1713 | L9: 1793 | M9: 1793 | N9: =AVERAGE(L9:M9) -> 1793 | O9: 1872 | P9: 1872 | Q9: =AVERAGE(O9:P9) -> 1872 | R9: 1593.5 | S9: 1.239 | T9: 1.1204 | U9: 107.46 | V9: 1286.12 | W9: 1301.93 | X9: =R9/T9 -> 1422.2599 | Y9: 1.2397
B10: 44014 | C10: 1601.5 | D10: 1601.5 | E10: =AVERAGE(C10:D10) -> 1601.5 | F10: 1621.5 | G10: 1621.5 | H10: =AVERAGE(F10:G10) -> 1621.5 | I10: 1720.5 | J10: 1720.5 | K10: =AVERAGE(I10:J10) -> 1720.5 | L10: 1801.5 | M10: 1801.5 | N10: =AVERAGE(L10:M10) -> 1801.5 | O10: 1880.5 | P10: 1880.5 | Q10: =AVERAGE(O10:P10) -> 1880.5 | R10: 1601.5 | S10: 1.2519 | T10: 1.1287 | U10: 107.46 | V10: 1279.26 | W10: 1294.51 | X10: =R10/T10 -> 1418.889 | Y10: 1.2526
B11: 44015 | C11: 1581.5 | D11: 1581.5 | E11: =AVERAGE(C11:D11) -> 1581.5 | F11: 1614 | G11: 1614 | H11: =AVERAGE(F11:G11) -> 1614 | I11: 1716 | J11: 1716 | K11: =AVERAGE(I11:J11) -> 1716 | L11: 1797 | M11: 1797 | N11: =AVERAGE(L11:M11) -> 1797 | O11: 1876 | P11: 1876 | Q11: =AVERAGE(O11:P11) -> 1876 | R11: 1581.5 | S11: 1.2454 | T11: 1.1224 | U11: 107.53 | V11: 1269.87 | W11: 1295.35 | X11: =R11/T11 -> 1409.0342 | Y11: 1.246
B12: 44018 | C12: 1593 | D12: 1593 | E12: =AVERAGE(C12:D12) -> 1593 | F12: 1626 | G12: 1626 | H12: =AVERAGE(F12:G12) -> 1626 | I12: 1725 | J12: 1725 | K12: =AVERAGE(I12:J12) -> 1725 | L12: 1804.5 | M12: 1804.5 | N12: =AVERAGE(L12:M12) -> 1804.5 | O12: 1883.5 | P12: 1883.5 | Q12: =AVERAGE(O12:P12) -> 1883.5 | R12: 1593 | S12: 1.251 | T12: 1.1319 | U12: 107.53 | V12: 1273.38 | W12: 1299.03 | X12: =R12/T12 -> 1407.3681 | Y12: 1.2517
B13: 44019 | C13: 1596.5 | D13: 1596.5 | E13: =AVERAGE(C13:D13) -> 1596.5 | F13: 1630 | G13: 1630 | H13: =AVERAGE(F13:G13) -> 1630 | I13: 1726 | J13: 1726 | K13: =AVERAGE(I13:J13) -> 1726 | L13: 1804.5 | M13: 1804.5 | N13: =AVERAGE(L13:M13) -> 1804.5 | O13: 1883.5 | P13: 1883.5 | Q13: =AVERAGE(O13:P13) -> 1883.5 | R13: 1596.5 | S13: 1.2519 | T13: 1.1291 | U13: 107.72 | V13: 1275.26 | W13: 1301.29 | X13: =R13/T13 -> 1413.958 | Y13: 1.2526
B14: 44020 | C14: 1619 | D14: 1619 | E14: =AVERAGE(C14:D14) -> 1619 | F14: 1651 | G14: 1651 | H14: =AVERAGE(F14:G14) -> 1651 | I14: 1743 | J14: 1743 | K14: =AVERAGE(I14:J14) -> 1743 | L14: 1822 | M14: 1822 | N14: =AVERAGE(L14:M14) -> 1822 | O14: 1901 | P14: 1901 | Q14: =AVERAGE(O14:P14) -> 1901 | R14: 1619 | S14: 1.2559 | T14: 1.129 | U14: 107.52 | V14: 1289.12 | W14: 1313.86 | X14: =R14/T14 -> 1434.0124 | Y14: 1.2566
B15: 44021 | C15: 1659.5 | D15: 1659.5 | E15: =AVERAGE(C15:D15) -> 1659.5 | F15: 1687 | G15: 1687 | H15: =AVERAGE(F15:G15) -> 1687 | I15: 1772 | J15: 1772 | K15: =AVERAGE(I15:J15) -> 1772 | L15: 1848 | M15: 1848 | N15: =AVERAGE(L15:M15) -> 1848 | O15: 1926 | P15: 1926 | Q15: =AVERAGE(O15:P15) -> 1926 | R15: 1659.5 | S15: 1.2652 | T15: 1.1343 | U15: 107.29 | V15: 1311.65 | W15: 1332.75 | X15: =R15/T15 -> 1463.0168 | Y15: 1.2658
B16: 44022 | C16: 1639.5 | D16: 1639.5 | E16: =AVERAGE(C16:D16) -> 1639.5 | F16: 1669 | G16: 1669 | H16: =AVERAGE(F16:G16) -> 1669 | I16: 1753.5 | J16: 1753.5 | K16: =AVERAGE(I16:J16) -> 1753.5 | L16: 1828 | M16: 1828 | N16: =AVERAGE(L16:M16) -> 1828 | O16: 1906 | P16: 1906 | Q16: =AVERAGE(O16:P16) -> 1906 | R16: 1639.5 | S16: 1.2599 | T16: 1.1286 | U16: 106.86 | V16: 1301.29 | W16: 1323.97 | X16: =R16/T16 -> 1452.6847 | Y16: 1.2606
B17: 44025 | C17: 1664.5 | D17: 1664.5 | E17: =AVERAGE(C17:D17) -> 1664.5 | F17: 1695.5 | G17: 1695.5 | H17: =AVERAGE(F17:G17) -> 1695.5 | I17: 1779 | J17: 1779 | K17: =AVERAGE(I17:J17) -> 1779 | L17: 1853.5 | M17: 1853.5 | N17: =AVERAGE(L17:M17) -> 1853.5 | O17: 1931 | P17: 1931 | Q17: =AVERAGE(O17:P17) -> 1931 | R17: 1664.5 | S17: 1.2604 | T17: 1.1335 | U17: 107.1 | V17: 1320.61 | W17: 1344.35 | X17: =R17/T17 -> 1468.4605 | Y17: 1.2612
B18: 44026 | C18: 1640 | D18: 1640 | E18: =AVERAGE(C18:D18) -> 1640 | F18: 1675 | G18: 1675 | H18: =AVERAGE(F18:G18) -> 1675 | I18: 1757 | J18: 1757 | K18: =AVERAGE(I18:J18) -> 1757 | L18: 1831 | M18: 1831 | N18: =AVERAGE(L18:M18) -> 1831 | O18: 1909 | P18: 1909 | Q18: =AVERAGE(O18:P18) -> 1909 | R18: 1640 | S18: 1.253 | T18: 1.1378 | U18: 107.37 | V18: 1308.86 | W18: 1336.05 | X18: =R18/T18 -> 1441.3781 | Y18: 1.2537
B19: 44027 | C19: 1651 | D19: 1651 | E19: =AVERAGE(C19:D19) -> 1651 | F19: 1686 | G19: 1686 | H19: =AVERAGE(F19:G19) -> 1686 | I19: 1771.5 | J19: 1771.5 | K19: =AVERAGE(I19:J19) -> 1771.5 | L19: 1845.5 | M19: 1845.5 | N19: =AVERAGE(L19:M19) -> 1845.5 | O19: 1923 | P19: 1923 | Q19: =AVERAGE(O19:P19) -> 1923 | R19: 1651 | S19: 1.2632 | T19: 1.1439 | U19: 106.9 | V19: 1307 | W19: 1333.97 | X19: =R19/T19 -> 1443.308 | Y19: 1.2639
B20: 44028 | C20: 1627 | D20: 1627 | E20: =AVERAGE(C20:D20) -> 1627 | F20: 1660.5 | G20: 1660.5 | H20: =AVERAGE(F20:G20) -> 1660.5 | I20: 1750 | J20: 1750 | K20: =AVERAGE(I20:J20) -> 1750 | L20: 1826 | M20: 1826 | N20: =AVERAGE(L20:M20) -> 1826 | O20: 1903.5 | P20: 1903.5 | Q20: =AVERAGE(O20:P20) -> 1903.5 | R20: 1627 | S20: 1.2555 | T20: 1.1413 | U20: 107.09 | V20: 1295.9 | W20: 1321.95 | X20: =R20/T20 -> 1425.5673 | Y20: 1.2561
... B31: 44043 | C31: 1685.5 | D31: 1685.5 | E31: =AVERAGE(C31:D31) -> 1685.5 | F31: 1722 | G31: 1722 | H31: =AVERAGE(F31:G31) -> 1722 | I31: 1796 | J31: 1796 | K31: =AVERAGE(I31:J31) -> 1796 | L31: 1867 | M31: 1867 | N31: =AVERAGE(L31:M31) -> 1867 | O31: 1942 | P31: 1942 | Q31: =AVERAGE(O31:P31) -> 1942 | R31: 1685.5 | S31: 1.3142 | T31: 1.1841 | U31: 104.91 | V31: 1282.53 | W31: 1309.7 | X31: =R31/T31 -> 1423.444 | Y31: 1.3148
B32: Average | C32: =ROUND(AVERAGE(C9:C31),2) -> 1639.35 | D32: =ROUND(AVERAGE(D9:D31),2) -> 1639.35 | E32: =ROUND(AVERAGE(C32:D32),2) -> 1639.35 | F32: =ROUND(AVERAGE(F9:F31),2) -> 1672.93 | G32: =ROUND(AVERAGE(G9:G31),2) -> 1672.93 | H32: =ROUND(AVERAGE(F32:G32),2) -> 1672.93 | I32: =ROUND(AVERAGE(I9:I31),2) -> 1761.28 | J32: =ROUND(AVERAGE(J9:J31),2) -> 1761.28 | K32: =ROUND(AVERAGE(I32:J32),2) -> 1761.28 | L32: =ROUND(AVERAGE(L9:L31),2) -> 1837.17 | M32: =ROUND(AVERAGE(M9:M31),2) -> 1837.17 | N32: =ROUND(AVERAGE(L32:M32),2) -> 1837.17 | O32: =ROUND(AVERAGE(O9:O31),2) -> 1915 | P32: =ROUND(AVERAGE(P9:P31),2) -> 1915 | Q32: =ROUND(AVERAGE(O32:P32),2) -> 1915 | R32: =ROUND(AVERAGE(R9:R31),2) -> 1639.35 | S32: =ROUND(AVERAGE(S9:S31),4) -> 1.267 | T32: =ROUND(AVERAGE(T9:T31),4) -> 1.1462 | U32: =ROUND(AVERAGE(U9:U31),2) -> 106.77 | V32: =AVERAGE(V9:V31) -> 1293.8822 | W32: =AVERAGE(W9:W31) -> 1319.6778 | X32: =AVERAGE(X9:X31) -> 1430.2509 | Y32: =AVERAGE(Y9:Y31) -> 1.2676261
B33: High | C33: =MAX(C9:C31) -> 1687 | D33: =MAX(D9:D31) -> 1687 | E33: =MAX(E9:E31) -> 1687 | F33: =MAX(F9:F31) -> 1726.5 | G33: =MAX(G9:G31) -> 1726.5 | H33: =MAX(H9:H31) -> 1726.5 | I33: =MAX(I9:I31) -> 1809 | J33: =MAX(J9:J31) -> 1809 | ... Y33: =MAX(Y9:Y31) -> 1.3148
B34: Low | C34: =MIN(C9:C31) -> 1581.5 | D34: =MIN(D9:D31) -> 1581.5 | E34: =MIN(E9:E31) -> 1581.5 | F34: =MIN(F9:F31) -> 1614 | G34: =MIN(G9:G31) -> 1614 | H34: =MIN(H9:H31) -> 1614 | I34: =MIN(I9:I31) -> 1713 | J34: =MIN(J9:J31) -> 1713 | ... Y34: =MIN(Y9:Y31) -> 1.2397
B36: Neither the LME nor any of its directors, officers or employees shall, except in the case of fraud or wilful neglect, be under any liability whatsoever either in
B37: contract or in tort in respect of any act or omission (including negligence) in relation to the preparation or publication of the data contained in the report

Sheet Zinc
B3: LME DAILY OFFICIAL AND SETTLEMENT PRICES
B4: LME ZINC $USD/Tonne
B6: 44013
C7: CASH | F7: 3-MONTHS | I7: DECEMBER 1 | L7: DECEMBER 2 | O7: DECEMBER 3 | R7: SETTLEMENT | S7: Exchange Rate | V7: Sterling Equivalents | X7: Euro Equivalents | Y7: 3MStg/$
C8: BUYER | D8: SELLER | E8: Mean | F8: BUYER | G8: SELLER | H8: Mean | I8: BUYER | J8: SELLER | K8: Mean | L8: BUYER | M8: SELLER | N8: Mean | O8: BUYER | P8: SELLER | Q8: Mean | S8: Stg/$ | T8: EURO | U8: Yen | V8: Cash Seller's | W8: 3mths Seller's | X8: Cash Seller's | Y8: 3MStg/$
B9: 44013 | C9: 2007.5 | D9: 2007.5 | E9: =AVERAGE(C9:D9) -> 2007.5 | F9: 2021.5 | G9: 2021.5 | H9: =AVERAGE(F9:G9) -> 2021.5 | I9: 2064 | J9: 2064 | K9: =AVERAGE(I9:J9) -> 2064 | L9: 2092 | M9: 2092 | N9: =AVERAGE(L9:M9) -> 2092 | O9: 2099.5 | P9: 2099.5 | Q9: =AVERAGE(O9:P9) -> 2099.5 | R9: 2007.5 | S9: 1.239 | T9: 1.1204 | U9: 107.46 | V9: 1620.26 | W9: 1630.64 | X9: =R9/T9 -> 1791.7708 | Y9: 1.2397
B10: 44014 | C10: 2035.5 | D10: 2035.5 | E10: =AVERAGE(C10:D10) -> 2035.5 | F10: 2049 | G10: 2049 | H10: =AVERAGE(F10:G10) -> 2049 | I10: 2093.5 | J10: 2093.5 | K10: =AVERAGE(I10:J10) -> 2093.5 | L10: 2121.5 | M10: 2121.5 | N10: =AVERAGE(L10:M10) -> 2121.5 | O10: 2129 | P10: 2129 | Q10: =AVERAGE(O10:P10) -> 2129 | R10: 2035.5 | S10: 1.2519 | T10: 1.1287 | U10: 107.46 | V10: 1625.93 | W10: 1635.8 | X10: =R10/T10 -> 1803.4021 | Y10: 1.2526
B11: 44015 | C11: 2020 | D11: 2020 | E11: =AVERAGE(C11:D11) -> 2020 | F11: 2030 | G11: 2030 | H11: =AVERAGE(F11:G11) -> 2030 | I11: 2077.5 | J11: 2077.5 | K11: =AVERAGE(I11:J11) -> 2077.5 | L11: 2105.5 | M11: 2105.5 | N11: =AVERAGE(L11:M11) -> 2105.5 | O11: 2113 | P11: 2113 | Q11: =AVERAGE(O11:P11) -> 2113 | R11: 2020 | S11: 1.2454 | T11: 1.1224 | U11: 107.53 | V11: 1621.97 | W11: 1629.21 | X11: =R11/T11 -> 1799.7149 | Y11: 1.246
B12: 44018 | C12: 2037.5 | D12: 2037.5 | E12: =AVERAGE(C12:D12) -> 2037.5 | F12: 2048 | G12: 2048 | H12: =AVERAGE(F12:G12) -> 2048 | I12: 2093.5 | J12: 2093.5 | K12: =AVERAGE(I12:J12) -> 2093.5 | L12: 2121.5 | M12: 2121.5 | N12: =AVERAGE(L12:M12) -> 2121.5 | O12: 2129 | P12: 2129 | Q12: =AVERAGE(O12:P12) -> 2129 | R12: 2037.5 | S12: 1.251 | T12: 1.1319 | U12: 107.53 | V12: 1628.7 | W12: 1636.17 | X12: =R12/T12 -> 1800.0707 | Y12: 1.2517
B13: 44019 | C13: 2023.5 | D13: 2023.5 | E13: =AVERAGE(C13:D13) -> 2023.5 | F13: 2035.5 | G13: 2035.5 | H13: =AVERAGE(F13:G13) -> 2035.5 | I13: 2082 | J13: 2082 | K13: =AVERAGE(I13:J13) -> 2082 | L13: 2110 | M13: 2110 | N13: =AVERAGE(L13:M13) -> 2110 | O13: 2117.5 | P13: 2117.5 | Q13: =AVERAGE(O13:P13) -> 2117.5 | R13: 2023.5 | S13: 1.2519 | T13: 1.1291 | U13: 107.72 | V13: 1616.34 | W13: 1625.02 | X13: =R13/T13 -> 1792.1353 | Y13: 1.2526
B14: 44020 | C14: 2094.5 | D14: 2094.5 | E14: =AVERAGE(C14:D14) -> 2094.5 | F14: 2107 | G14: 2107 | H14: =AVERAGE(F14:G14) -> 2107 | I14: 2151.5 | J14: 2151.5 | K14: =AVERAGE(I14:J14) -> 2151.5 | L14: 2179.5 | M14: 2179.5 | N14: =AVERAGE(L14:M14) -> 2179.5 | O14: 2187 | P14: 2187 | Q14: =AVERAGE(O14:P14) -> 2187 | R14: 2094.5 | S14: 1.2559 | T14: 1.129 | U14: 107.52 | V14: 1667.73 | W14: 1676.75 | X14: =R14/T14 -> 1855.1816 | Y14: 1.2566
B15: 44021 | C15: 2132.5 | D15: 2132.5 | E15: =AVERAGE(C15:D15) -> 2132.5 | F15: 2145 | G15: 2145 | H15: =AVERAGE(F15:G15) -> 2145 | I15: 2190 | J15: 2190 | K15: =AVERAGE(I15:J15) -> 2190 | L15: 2212 | M15: 2212 | N15: =AVERAGE(L15:M15) -> 2212 | O15: 2219.5 | P15: 2219.5 | Q15: =AVERAGE(O15:P15) -> 2219.5 | R15: 2132.5 | S15: 1.2652 | T15: 1.1343 | U15: 107.29 | V15: 1685.5 | W15: 1694.58 | X15: =R15/T15 -> 1880.0141 | Y15: 1.2658
B16: 44022 | C16: 2145.5 | D16: 2145.5 | E16: =AVERAGE(C16:D16) -> 2145.5 | F16: 2156.5 | G16: 2156.5 | H16: =AVERAGE(F16:G16) -> 2156.5 | I16: 2201 | J16: 2201 | K16: =AVERAGE(I16:J16) -> 2201 | L16: 2225 | M16: 2225 | N16: =AVERAGE(L16:M16) -> 2225 | O16: 2232.5 | P16: 2232.5 | Q16: =AVERAGE(O16:P16) -> 2232.5 | R16: 2145.5 | S16: 1.2599 | T16: 1.1286 | U16: 106.86 | V16: 1702.91 | W16: 1710.69 | X16: =R16/T16 -> 1901.0278 | Y16: 1.2606
B17: 44025 | C17: 2215.5 | D17: 2215.5 | E17: =AVERAGE(C17:D17) -> 2215.5 | F17: 2223.5 | G17: 2223.5 | H17: =AVERAGE(F17:G17) -> 2223.5 | I17: 2263 | J17: 2263 | K17: =AVERAGE(I17:J17) -> 2263 | L17: 2285 | M17: 2285 | N17: =AVERAGE(L17:M17) -> 2285 | O17: 2292.5 | P17: 2292.5 | Q17: =AVERAGE(O17:P17) -> 2292.5 | R17: 2215.5 | S17: 1.2604 | T17: 1.1335 | U17: 107.1 | V17: 1757.78 | W17: 1763 | X17: =R17/T17 -> 1954.5655 | Y17: 1.2612
B18: 44026 | C18: 2187.5 | D18: 2187.5 | E18: =AVERAGE(C18:D18) -> 2187.5 | F18: 2198.5 | G18: 2198.5 | H18: =AVERAGE(F18:G18) -> 2198.5 | I18: 2238 | J18: 2238 | K18: =AVERAGE(I18:J18) -> 2238 | L18: 2260 | M18: 2260 | N18: =AVERAGE(L18:M18) -> 2260 | O18: 2267.5 | P18: 2267.5 | Q18: =AVERAGE(O18:P18) -> 2267.5 | R18: 2187.5 | S18: 1.253 | T18: 1.1378 | U18: 107.37 | V18: 1745.81 | W18: 1753.61 | X18: =R18/T18 -> 1922.5699 | Y18: 1.2537
B19: 44027 | C19: 2198.5 | D19: 2198.5 | E19: =AVERAGE(C19:D19) -> 2198.5 | F19: 2209.5 | G19: 2209.5 | H19: =AVERAGE(F19:G19) -> 2209.5 | I19: 2249.5 | J19: 2249.5 | K19: =AVERAGE(I19:J19) -> 2249.5 | L19: 2271.5 | M19: 2271.5 | N19: =AVERAGE(L19:M19) -> 2271.5 | O19: 2279 | P19: 2279 | Q19: =AVERAGE(O19:P19) -> 2279 | R19: 2198.5 | S19: 1.2632 | T19: 1.1439 | U19: 106.9 | V19: 1740.42 | W19: 1748.16 | X19: =R19/T19 -> 1921.9337 | Y19: 1.2639
B20: 44028 | C20: 2188 | D20: 2188 | E20: =AVERAGE(C20:D20) -> 2188 | F20: 2198 | G20: 2198 | H20: =AVERAGE(F20:G20) -> 2198 | I20: 2233.5 | J20: 2233.5 | K20: =AVERAGE(I20:J20) -> 2233.5 | L20: 2255 | M20: 2255 | N20: =AVERAGE(L20:M20) -> 2255 | O20: 2263 | P20: 2263 | Q20: =AVERAGE(O20:P20) -> 2263 | R20: 2188 | S20: 1.2555 | T20: 1.1413 | U20: 107.09 | V20: 1742.73 | W20: 1749.86 | X20: =R20/T20 -> 1917.1121 | Y20: 1.2561
... B31: 44043 | C31: 2299 | D31: 2299 | E31: =AVERAGE(C31:D31) -> 2299 | F31: 2311 | G31: 2311 | H31: =AVERAGE(F31:G31) -> 2311 | I31: 2345.5 | J31: 2345.5 | K31: =AVERAGE(I31:J31) -> 2345.5 | L31: 2372.5 | M31: 2372.5 | N31: =AVERAGE(L31:M31) -> 2372.5 | O31: 2380 | P31: 2380 | Q31: =AVERAGE(O31:P31) -> 2380 | R31: 2299 | S31: 1.3142 | T31: 1.1841 | U31: 104.91 | V31: 1749.35 | W31: 1757.68 | X31: =R31/T31 -> 1941.559 | Y31: 1.3148
B32: Average | C32: =ROUND(AVERAGE(C9:C31),2) -> 2162.24 | D32: =ROUND(AVERAGE(D9:D31),2) -> 2162.24 | E32: =ROUND(AVERAGE(C32:D32),2) -> 2162.24 | F32: =ROUND(AVERAGE(F9:F31),2) -> 2172.89 | G32: =ROUND(AVERAGE(G9:G31),2) -> 2172.89 | H32: =ROUND(AVERAGE(F32:G32),2) -> 2172.89 | I32: =ROUND(AVERAGE(I9:I31),2) -> 2214.02 | J32: =ROUND(AVERAGE(J9:J31),2) -> 2214.02 | K32: =ROUND(AVERAGE(I32:J32),2) -> 2214.02 | L32: =ROUND(AVERAGE(L9:L31),2) -> 2240.04 | M32: =ROUND(AVERAGE(M9:M31),2) -> 2240.04 | N32: =ROUND(AVERAGE(L32:M32),2) -> 2240.04 | O32: =ROUND(AVERAGE(O9:O31),2) -> 2247.57 | P32: =ROUND(AVERAGE(P9:P31),2) -> 2247.57 | Q32: =ROUND(AVERAGE(O32:P32),2) -> 2247.57 | R32: =ROUND(AVERAGE(R9:R31),2) -> 2162.24 | S32: =ROUND(AVERAGE(S9:S31),4) -> 1.267 | T32: =ROUND(AVERAGE(T9:T31),4) -> 1.1462 | U32: =ROUND(AVERAGE(U9:U31),2) -> 106.77 | V32: =AVERAGE(V9:V31) -> 1706.1948 | W32: =AVERAGE(W9:W31) -> 1713.7261 | X32: =AVERAGE(X9:X31) -> 1885.9336 | Y32: =AVERAGE(Y9:Y31) -> 1.2676261
B33: High | C33: =MAX(C9:C31) -> 2299 | D33: =MAX(D9:D31) -> 2299 | E33: =MAX(E9:E31) -> 2299 | F33: =MAX(F9:F31) -> 2311 | G33: =MAX(G9:G31) -> 2311 | H33: =MAX(H9:H31) -> 2311 | I33: =MAX(I9:I31) -> 2345.5 | J33: =MAX(J9:J31) -> 2345.5 | ... Y33: =MAX(Y9:Y31) -> 1.3148
B34: Low | C34: =MIN(C9:C31) -> 2007.5 | D34: =MIN(D9:D31) -> 2007.5 | E34: =MIN(E9:E31) -> 2007.5 | F34: =MIN(F9:F31) -> 2021.5 | G34: =MIN(G9:G31) -> 2021.5 | H34: =MIN(H9:H31) -> 2021.5 | I34: =MIN(I9:I31) -> 2064 | J34: =MIN(J9:J31) -> 2064 | ... Y34: =MIN(Y9:Y31) -> 1.2397
B36: Neither the LME nor any of its directors, officers or employees shall, except in the case of fraud or wilful neglect, be under any liability whatsoever either in
B37: contract or in tort in respect of any act or omission (including negligence) in relation to the preparation or publication of the data contained in the report

Sheet Lead
B3: LME DAILY OFFICIAL AND SETTLEMENT PRICES
B4: LME LEAD $USD/Tonne
B6: 44013
C7: CASH | F7: 3-MONTHS | I7: DECEMBER 1 | L7: DECEMBER 2 | O7: DECEMBER 3 | R7: SETTLEMENT | S7: Exchange Rate | V7: Sterling Equivalents | X7: Euro Equivalents | Y7: 3MStg/$
C8: BUYER | D8: SELLER | E8: Mean | F8: BUYER | G8: SELLER | H8: Mean | I8: BUYER | J8: SELLER | K8: Mean | L8: BUYER | M8: SELLER | N8: Mean | O8: BUYER | P8: SELLER | Q8: Mean | S8: Stg/$ | T8: EURO | U8: Yen | V8: Cash Seller's | W8: 3mths Seller's | X8: Cash Seller's | Y8: 3MStg/$
B9: 44013 | C9: 1761 | D9: 1761 | E9: =AVERAGE(C9:D9) -> 1761 | F9: 1773.5 | G9: 1773.5 | H9: =AVERAGE(F9:G9) -> 1773.5 | I9: 1817 | J9: 1817 | K9: =AVERAGE(I9:J9) -> 1817 | L9: 1851 | M9: 1851 | N9: =AVERAGE(L9:M9) -> 1851 | O9: 1871 | P9: 1871 | Q9: =AVERAGE(O9:P9) -> 1871 | R9: 1761 | S9: 1.239 | T9: 1.1204 | U9: 107.46 | V9: 1421.31 | W9: 1430.59 | X9: =R9/T9 -> 1571.7601 | Y9: 1.2397
B10: 44014 | C10: 1765.5 | D10: 1765.5 | E10: =AVERAGE(C10:D10) -> 1765.5 | F10: 1780 | G10: 1780 | H10: =AVERAGE(F10:G10) -> 1780 | I10: 1824 | J10: 1824 | K10: =AVERAGE(I10:J10) -> 1824 | L10: 1858 | M10: 1858 | N10: =AVERAGE(L10:M10) -> 1858 | O10: 1878 | P10: 1878 | Q10: =AVERAGE(O10:P10) -> 1878 | R10: 1765.5 | S10: 1.2519 | T10: 1.1287 | U10: 107.46 | V10: 1410.26 | W10: 1421.04 | X10: =R10/T10 -> 1564.1889 | Y10: 1.2526
B11: 44015 | C11: 1756 | D11: 1756 | E11: =AVERAGE(C11:D11) -> 1756 | F11: 1770 | G11: 1770 | H11: =AVERAGE(F11:G11) -> 1770 | I11: 1819 | J11: 1819 | K11: =AVERAGE(I11:J11) -> 1819 | L11: 1853 | M11: 1853 | N11: =AVERAGE(L11:M11) -> 1853 | O11: 1873 | P11: 1873 | Q11: =AVERAGE(O11:P11) -> 1873 | R11: 1756 | S11: 1.2454 | T11: 1.1224 | U11: 107.53 | V11: 1409.99 | W11: 1420.55 | X11: =R11/T11 -> 1564.5046 | Y11: 1.246
B12: 44018 | C12: 1781 | D12: 1781 | E12: =AVERAGE(C12:D12) -> 1781 | F12: 1794.5 | G12: 1794.5 | H12: =AVERAGE(F12:G12) -> 1794.5 | I12: 1840.5 | J12: 1840.5 | K12: =AVERAGE(I12:J12) -> 1840.5 | L12: 1874.5 | M12: 1874.5 | N12: =AVERAGE(L12:M12) -> 1874.5 | O12: 1894.5 | P12: 1894.5 | Q12: =AVERAGE(O12:P12) -> 1894.5 | R12: 1781 | S12: 1.251 | T12: 1.1319 | U12: 107.53 | V12: 1423.66 | W12: 1433.65 | X12: =R12/T12 -> 1573.4606 | Y12: 1.2517
B13: 44019 | C13: 1779 | D13: 1779 | E13: =AVERAGE(C13:D13) -> 1779 | F13: 1792.5 | G13: 1792.5 | H13: =AVERAGE(F13:G13) -> 1792.5 | I13: 1837 | J13: 1837 | K13: =AVERAGE(I13:J13) -> 1837 | L13: 1871 | M13: 1871 | N13: =AVERAGE(L13:M13) -> 1871 | O13: 1891 | P13: 1891 | Q13: =AVERAGE(O13:P13) -> 1891 | R13: 1779 | S13: 1.2519 | T13: 1.1291 | U13: 107.72 | V13: 1421.04 | W13: 1431.02 | X13: =R13/T13 -> 1575.5912 | Y13: 1.2526
B14: 44020 | C14: 1819.5 | D14: 1819.5 | E14: =AVERAGE(C14:D14) -> 1819.5 | F14: 1831.5 | G14: 1831.5 | H14: =AVERAGE(F14:G14) -> 1831.5 | I14: 1875.5 | J14: 1875.5 | K14: =AVERAGE(I14:J14) -> 1875.5 | L14: 1911.5 | M14: 1911.5 | N14: =AVERAGE(L14:M14) -> 1911.5 | O14: 1931.5 | P14: 1931.5 | Q14: =AVERAGE(O14:P14) -> 1931.5 | R14: 1819.5 | S14: 1.2559 | T14: 1.129 | U14: 107.52 | V14: 1448.76 | W14: 1457.5 | X14: =R14/T14 -> 1611.6032 | Y14: 1.2566
B15: 44021 | C15: 1817.5 | D15: 1817.5 | E15: =AVERAGE(C15:D15) -> 1817.5 | F15: 1828.5 | G15: 1828.5 | H15: =AVERAGE(F15:G15) -> 1828.5 | I15: 1870.5 | J15: 1870.5 | K15: =AVERAGE(I15:J15) -> 1870.5 | L15: 1901.5 | M15: 1901.5 | N15: =AVERAGE(L15:M15) -> 1901.5 | O15: 1926.5 | P15: 1926.5 | Q15: =AVERAGE(O15:P15) -> 1926.5 | R15: 1817.5 | S15: 1.2652 | T15: 1.1343 | U15: 107.29 | V15: 1436.53 | W15: 1444.54 | X15: =R15/T15 -> 1602.3098 | Y15: 1.2658
B16: 44022 | C16: 1842 | D16: 1842 | E16: =AVERAGE(C16:D16) -> 1842 | F16: 1851 | G16: 1851 | H16: =AVERAGE(F16:G16) -> 1851 | I16: 1887.5 | J16: 1887.5 | K16: =AVERAGE(I16:J16) -> 1887.5 | L16: 1918.5 | M16: 1918.5 | N16: =AVERAGE(L16:M16) -> 1918.5 | O16: 1946 | P16: 1946 | Q16: =AVERAGE(O16:P16) -> 1946 | R16: 1842 | S16: 1.2599 | T16: 1.1286 | U16: 106.86 | V16: 1462.02 | W16: 1468.35 | X16: =R16/T16 -> 1632.1106 | Y16: 1.2606
B17: 44025 | C17: 1858 | D17: 1858 | E17: =AVERAGE(C17:D17) -> 1858 | F17: 1870 | G17: 1870 | H17: =AVERAGE(F17:G17) -> 1870 | I17: 1906 | J17: 1906 | K17: =AVERAGE(I17:J17) -> 1906 | L17: 1936.5 | M17: 1936.5 | N17: =AVERAGE(L17:M17) -> 1936.5 | O17: 1964 | P17: 1964 | Q17: =AVERAGE(O17:P17) -> 1964 | R17: 1858 | S17: 1.2604 | T17: 1.1335 | U17: 107.1 | V17: 1474.14 | W17: 1482.71 | X17: =R17/T17 -> 1639.1707 | Y17: 1.2612
B18: 44026 | C18: 1839.5 | D18: 1839.5 | E18: =AVERAGE(C18:D18) -> 1839.5 | F18: 1858 | G18: 1858 | H18: =AVERAGE(F18:G18) -> 1858 | I18: 1892.5 | J18: 1892.5 | K18: =AVERAGE(I18:J18) -> 1892.5 | L18: 1923.5 | M18: 1923.5 | N18: =AVERAGE(L18:M18) -> 1923.5 | O18: 1951 | P18: 1951 | Q18: =AVERAGE(O18:P18) -> 1951 | R18: 1839.5 | S18: 1.253 | T18: 1.1378 | U18: 107.37 | V18: 1468.08 | W18: 1482.01 | X18: =R18/T18 -> 1616.7165 | Y18: 1.2537
B19: 44027 | C19: 1836 | D19: 1836 | E19: =AVERAGE(C19:D19) -> 1836 | F19: 1853.5 | G19: 1853.5 | H19: =AVERAGE(F19:G19) -> 1853.5 | I19: 1889 | J19: 1889 | K19: =AVERAGE(I19:J19) -> 1889 | L19: 1920 | M19: 1920 | N19: =AVERAGE(L19:M19) -> 1920 | O19: 1947.5 | P19: 1947.5 | Q19: =AVERAGE(O19:P19) -> 1947.5 | R19: 1836 | S19: 1.2632 | T19: 1.1439 | U19: 106.9 | V19: 1453.45 | W19: 1466.49 | X19: =R19/T19 -> 1605.0354 | Y19: 1.2639
B20: 44028 | C20: 1824 | D20: 1824 | E20: =AVERAGE(C20:D20) -> 1824 | F20: 1840.5 | G20: 1840.5 | H20: =AVERAGE(F20:G20) -> 1840.5 | I20: 1876 | J20: 1876 | K20: =AVERAGE(I20:J20) -> 1876 | L20: 1906.5 | M20: 1906.5 | N20: =AVERAGE(L20:M20) -> 1906.5 | O20: 1934 | P20: 1934 | Q20: =AVERAGE(O20:P20) -> 1934 | R20: 1824 | S20: 1.2555 | T20: 1.1413 | U20: 107.09 | V20: 1452.81 | W20: 1465.25 | X20: =R20/T20 -> 1598.1775 | Y20: 1.2561
... B31: 44043 | C31: 1843 | D31: 1843 | E31: =AVERAGE(C31:D31) -> 1843 | F31: 1861 | G31: 1861 | H31: =AVERAGE(F31:G31) -> 1861 | I31: 1899.5 | J31: 1899.5 | K31: =AVERAGE(I31:J31) -> 1899.5 | L31: 1932.5 | M31: 1932.5 | N31: =AVERAGE(L31:M31) -> 1932.5 | O31: 1965.5 | P31: 1965.5 | Q31: =AVERAGE(O31:P31) -> 1965.5 | R31: 1843 | S31: 1.3142 | T31: 1.1841 | U31: 104.91 | V31: 1402.37 | W31: 1415.42 | X31: =R31/T31 -> 1556.4564 | Y31: 1.3148
B32: Average | C32: =ROUND(AVERAGE(C9:C31),2) -> 1812.15 | D32: =ROUND(AVERAGE(D9:D31),2) -> 1812.15 | E32: =ROUND(AVERAGE(C32:D32),2) -> 1812.15 | F32: =ROUND(AVERAGE(F9:F31),2) -> 1828.28 | G32: =ROUND(AVERAGE(G9:G31),2) -> 1828.28 | H32: =ROUND(AVERAGE(F32:G32),2) -> 1828.28 | I32: =ROUND(AVERAGE(I9:I31),2) -> 1868.33 | J32: =ROUND(AVERAGE(J9:J31),2) -> 1868.33 | K32: =ROUND(AVERAGE(I32:J32),2) -> 1868.33 | L32: =ROUND(AVERAGE(L9:L31),2) -> 1900.7 | M32: =ROUND(AVERAGE(M9:M31),2) -> 1900.7 | N32: =ROUND(AVERAGE(L32:M32),2) -> 1900.7 | O32: =ROUND(AVERAGE(O9:O31),2) -> 1927.8 | P32: =ROUND(AVERAGE(P9:P31),2) -> 1927.8 | Q32: =ROUND(AVERAGE(O32:P32),2) -> 1927.8 | R32: =ROUND(AVERAGE(R9:R31),2) -> 1812.15 | S32: =ROUND(AVERAGE(S9:S31),4) -> 1.267 | T32: =ROUND(AVERAGE(T9:T31),4) -> 1.1462 | U32: =ROUND(AVERAGE(U9:U31),2) -> 106.77 | V32: =AVERAGE(V9:V31) -> 1430.4222 | W32: =AVERAGE(W9:W31) -> 1442.3948 | X32: =AVERAGE(X9:X31) -> 1581.2178 | Y32: =AVERAGE(Y9:Y31) -> 1.2676261
B33: High | C33: =MAX(C9:C31) -> 1858 | D33: =MAX(D9:D31) -> 1858 | E33: =MAX(E9:E31) -> 1858 | F33: =MAX(F9:F31) -> 1870 | G33: =MAX(G9:G31) -> 1870 | H33: =MAX(H9:H31) -> 1870 | I33: =MAX(I9:I31) -> 1907 | J33: =MAX(J9:J31) -> 1907 | ... Y33: =MAX(Y9:Y31) -> 1.3148
B34: Low | C34: =MIN(C9:C31) -> 1756 | D34: =MIN(D9:D31) -> 1756 | E34: =MIN(E9:E31) -> 1756 | F34: =MIN(F9:F31) -> 1770 | G34: =MIN(G9:G31) -> 1770 | H34: =MIN(H9:H31) -> 1770 | I34: =MIN(I9:I31) -> 1817 | J34: =MIN(J9:J31) -> 1817 | ... Y34: =MIN(Y9:Y31) -> 1.2397
B36: Neither the LME nor any of its directors, officers or employees shall, except in the case of fraud or wilful neglect, be under any liability whatsoever either in
B37: contract or in tort in respect of any act or omission (including negligence) in relation to the preparation or publication of the data contained in the report

Sheet Tin
B3: LME DAILY OFFICIAL AND SETTLEMENT PRICES
B4: LME TIN $USD/Tonne
B6: 44013
C7: CASH | F7: 3-MONTHS | I7: 15-MONTHS | L7: SETTLEMENT | M7: Exchange Rate | P7: Sterling Equivalents | R7: Euro Equivalents | S7: 3MStg/$
C8: BUYER | D8: SELLER | E8: Mean | F8: BUYER | G8: SELLER | H8: Mean | I8: BUYER | J8: SELLER | K8: Mean | M8: Stg/$ | N8: EURO | O8: Yen | P8: Cash Seller's | Q8: 3mths Seller's | R8: Cash Seller's | S8: 3MStg/$
B9: 44013 | C9: 16920 | D9: 16920 | E9: =AVERAGE(C9:D9) -> 16920 | F9: 16795 | G9: 16795 | H9: =AVERAGE(F9:G9) -> 16795 | I9: 16563 | J9: 16563 | K9: =AVERAGE(I9:J9) -> 16563 | L9: 16920 | M9: 1.239 | N9: 1.1204 | O9: 107.46 | P9: 13656.17 | Q9: 13547.63 | R9: =L9/N9 -> 15101.749 | S9: 1.2397
B10: 44014 | C10: 16960 | D10: 16960 | E10: =AVERAGE(C10:D10) -> 16960 | F10: 16850 | G10: 16850 | H10: =AVERAGE(F10:G10) -> 16850 | I10: 16622 | J10: 16622 | K10: =AVERAGE(I10:J10) -> 16622 | L10: 16960 | M10: 1.2519 | N10: 1.1287 | O10: 107.46 | P10: 13547.41 | Q10: 13452.02 | R10: =L10/N10 -> 15026.136 | S10: 1.2526
B11: 44015 | C11: 16960 | D11: 16960 | E11: =AVERAGE(C11:D11) -> 16960 | F11: 16850 | G11: 16850 | H11: =AVERAGE(F11:G11) -> 16850 | I11: 16617 | J11: 16617 | K11: =AVERAGE(I11:J11) -> 16617 | L11: 16960 | M11: 1.2454 | N11: 1.1224 | O11: 107.53 | P11: 13618.11 | Q11: 13523.27 | R11: =L11/N11 -> 15110.478 | S11: 1.246
B12: 44018 | C12: 17150 | D12: 17150 | E12: =AVERAGE(C12:D12) -> 17150 | F12: 17030 | G12: 17030 | H12: =AVERAGE(F12:G12) -> 17030 | I12: 16803 | J12: 16803 | K12: =AVERAGE(I12:J12) -> 16803 | L12: 17150 | M12: 1.251 | N12: 1.1319 | O12: 107.53 | P12: 13709.03 | Q12: 13605.5 | R12: =L12/N12 -> 15151.515 | S12: 1.2517
B13: 44019 | C13: 17110 | D13: 17110 | E13: =AVERAGE(C13:D13) -> 17110 | F13: 17060 | G13: 17060 | H13: =AVERAGE(F13:G13) -> 17060 | I13: 16835 | J13: 16835 | K13: =AVERAGE(I13:J13) -> 16835 | L13: 17110 | M13: 1.2519 | N13: 1.1291 | O13: 107.72 | P13: 13667.23 | Q13: 13619.67 | R13: =L13/N13 -> 15153.662 | S13: 1.2526
B14: 44020 | C14: 17126 | D14: 17126 | E14: =AVERAGE(C14:D14) -> 17126 | F14: 17026 | G14: 17026 | H14: =AVERAGE(F14:G14) -> 17026 | I14: 16834 | J14: 16834 | K14: =AVERAGE(I14:J14) -> 16834 | L14: 17126 | M14: 1.2559 | N14: 1.129 | O14: 107.52 | P14: 13636.44 | Q14: 13549.26 | R14: =L14/N14 -> 15169.176 | S14: 1.2566
B15: 44021 | C15: 17455 | D15: 17455 | E15: =AVERAGE(C15:D15) -> 17455 | F15: 17328 | G15: 17328 | H15: =AVERAGE(F15:G15) -> 17328 | I15: 17147 | J15: 17147 | K15: =AVERAGE(I15:J15) -> 17147 | L15: 17455 | M15: 1.2652 | N15: 1.1343 | O15: 107.29 | P15: 13796.24 | Q15: 13689.37 | R15: =L15/N15 -> 15388.345 | S15: 1.2658
B16: 44022 | C16: 17080 | D16: 17080 | E16: =AVERAGE(C16:D16) -> 17080 | F16: 16958 | G16: 16958 | H16: =AVERAGE(F16:G16) -> 16958 | I16: 16775 | J16: 16775 | K16: =AVERAGE(I16:J16) -> 16775 | L16: 17080 | M16: 1.2599 | N16: 1.1286 | O16: 106.86 | P16: 13556.63 | Q16: 13452.32 | R16: =L16/N16 -> 15133.794 | S16: 1.2606
B17: 44025 | C17: 17377 | D17: 17377 | E17: =AVERAGE(C17:D17) -> 17377 | F17: 17278 | G17: 17278 | H17: =AVERAGE(F17:G17) -> 17278 | I17: 17081 | J17: 17081 | K17: =AVERAGE(I17:J17) -> 17081 | L17: 17377 | M17: 1.2604 | N17: 1.1335 | O17: 107.1 | P17: 13786.89 | Q17: 13699.65 | R17: =L17/N17 -> 15330.393 | S17: 1.2612
B18: 44026 | C18: 17225 | D18: 17225 | E18: =AVERAGE(C18:D18) -> 17225 | F18: 17170 | G18: 17170 | H18: =AVERAGE(F18:G18) -> 17170 | I18: 16961 | J18: 16961 | K18: =AVERAGE(I18:J18) -> 16961 | L18: 17225 | M18: 1.253 | N18: 1.1378 | O18: 107.37 | P18: 13747.01 | Q18: 13695.46 | R18: =L18/N18 -> 15138.864 | S18: 1.2537
B19: 44027 | C19: 17398 | D19: 17398 | E19: =AVERAGE(C19:D19) -> 17398 | F19: 17310 | G19: 17310 | H19: =AVERAGE(F19:G19) -> 17310 | I19: 17099 | J19: 17099 | K19: =AVERAGE(I19:J19) -> 17099 | L19: 17398 | M19: 1.2632 | N19: 1.1439 | O19: 106.9 | P19: 13772.96 | Q19: 13695.7 | R19: =L19/N19 -> 15209.371 | S19: 1.2639
B20: 44028 | C20: 17270 | D20: 17270 | E20: =AVERAGE(C20:D20) -> 17270 | F20: 17200 | G20: 17200 | H20: =AVERAGE(F20:G20) -> 17200 | I20: 16992 | J20: 16992 | K20: =AVERAGE(I20:J20) -> 16992 | L20: 17270 | M20: 1.2555 | N20: 1.1413 | O20: 107.09 | P20: 13755.48 | Q20: 13693.18 | R20: =L20/N20 -> 15131.867 | S20: 1.2561
... B31: 44043 | C31: 17880 | D31: 17880 | E31: =AVERAGE(C31:D31) -> 17880 | F31: 17822 | G31: 17822 | H31: =AVERAGE(F31:G31) -> 17822 | I31: 17584 | J31: 17584 | K31: =AVERAGE(I31:J31) -> 17584 | L31: 17880 | M31: 1.3142 | N31: 1.1841 | O31: 104.91 | P31: 13605.24 | Q31: 13554.91 | R31: =L31/N31 -> 15100.076 | S31: 1.3148
B32: Average | C32: =ROUND(AVERAGE(C9:C31),2) -> 17452.96 | D32: =ROUND(AVERAGE(D9:D31),2) -> 17452.96 | E32: =ROUND(AVERAGE(C32:D32),2) -> 17452.96 | F32: =ROUND(AVERAGE(F9:F31),2) -> 17375.48 | G32: =ROUND(AVERAGE(G9:G31),2) -> 17375.48 | H32: =ROUND(AVERAGE(F32:G32),2) -> 17375.48 | I32: =ROUND(AVERAGE(I9:I31),2) -> 17152.57 | J32: =ROUND(AVERAGE(J9:J31),2) -> 17152.57 | K32: =ROUND(AVERAGE(I32:J32),2) -> 17152.57 | L32: =ROUND(AVERAGE(L9:L31),2) -> 17452.96 | M32: =ROUND(AVERAGE(M9:M31),4) -> 1.267 | N32: =ROUND(AVERAGE(N9:N31),4) -> 1.1462 | O32: =ROUND(AVERAGE(O9:O31),2) -> 106.77 | P32: =AVERAGE(P9:P31) -> 13774.558 | Q32: =AVERAGE(Q9:Q31) -> 13706.1 | R32: =AVERAGE(R9:R31) -> 15225.813 | S32: =AVERAGE(S9:S31) -> 1.2676261
B33: High | C33: =MAX(C9:C31) -> 18195 | D33: =MAX(D9:D31) -> 18195 | E33: =MAX(E9:E31) -> 18195 | F33: =MAX(F9:F31) -> 18141 | G33: =MAX(G9:G31) -> 18141 | H33: =MAX(H9:H31) -> 18141 | I33: =MAX(I9:I31) -> 17886 | J33: =MAX(J9:J31) -> 17886 | ... S33: =MAX(S9:S31) -> 1.3148
B34: Low | C34: =MIN(C9:C31) -> 16920 | D34: =MIN(D9:D31) -> 16920 | E34: =MIN(E9:E31) -> 16920 | F34: =MIN(F9:F31) -> 16795 | G34: =MIN(G9:G31) -> 16795 | H34: =MIN(H9:H31) -> 16795 | I34: =MIN(I9:I31) -> 16563 | J34: =MIN(J9:J31) -> 16563 | ... S34: =MIN(S9:S31) -> 1.2397
B36: Neither the LME nor any of its directors, officers or employees shall, except in the case of fraud or wilful neglect, be under any liability whatsoever either in
B37: contract or in tort in respect of any act or omission (including negligence) in relation to the preparation or publication of the data contained in the report

Sheet Nickel
B3: LME DAILY OFFICIAL AND SETTLEMENT PRICES
B4: LME NICKEL $USD/Tonne
B6: 44013
C7: CASH | F7: 3-MONTHS | I7: DECEMBER 1 | L7: DECEMBER 2 | O7: DECEMBER 3 | R7: SETTLEMENT | S7: Exchange Rate | V7: Sterling Equivalents | X7: Euro Equivalents | Y7: 3MStg/$
C8: BUYER | D8: SELLER | E8: Mean | F8: BUYER | G8: SELLER | H8: Mean | I8: BUYER | J8: SELLER | K8: Mean | L8: BUYER | M8: SELLER | N8: Mean | O8: BUYER | P8: SELLER | Q8: Mean | S8: Stg/$ | T8: EURO | U8: Yen | V8: Cash Seller's | W8: 3mths Seller's | X8: Cash Seller's | Y8: 3MStg/$
B9: 44013 | C9: 12555 | D9: 12555 | E9: =AVERAGE(C9:D9) -> 12555 | F9: 12620 | G9: 12620 | H9: =AVERAGE(F9:G9) -> 12620 | I9: 12895 | J9: 12895 | K9: =AVERAGE(I9:J9) -> 12895 | L9: 13125 | M9: 13125 | N9: =AVERAGE(L9:M9) -> 13125 | O9: 13355 | P9: 13355 | Q9: =AVERAGE(O9:P9) -> 13355 | R9: 12555 | S9: 1.239 | T9: 1.1204 | U9: 107.46 | V9: 10133.17 | W9: 10179.88 | X9: =R9/T9 -> 11205.819 | Y9: 1.2397
B10: 44014 | C10: 12823 | D10: 12823 | E10: =AVERAGE(C10:D10) -> 12823 | F10: 12873 | G10: 12873 | H10: =AVERAGE(F10:G10) -> 12873 | I10: 13147 | J10: 13147 | K10: =AVERAGE(I10:J10) -> 13147 | L10: 13377 | M10: 13377 | N10: =AVERAGE(L10:M10) -> 13377 | O10: 13607 | P10: 13607 | Q10: =AVERAGE(O10:P10) -> 13607 | R10: 12823 | S10: 1.2519 | T10: 1.1287 | U10: 107.46 | V10: 10242.83 | W10: 10277.02 | X10: =R10/T10 -> 11360.858 | Y10: 1.2526
B11: 44015 | C11: 13040 | D11: 13040 | E11: =AVERAGE(C11:D11) -> 13040 | F11: 13089 | G11: 13089 | H11: =AVERAGE(F11:G11) -> 13089 | I11: 13358 | J11: 13358 | K11: =AVERAGE(I11:J11) -> 13358 | L11: 13588 | M11: 13588 | N11: =AVERAGE(L11:M11) -> 13588 | O11: 13818 | P11: 13818 | Q11: =AVERAGE(O11:P11) -> 13818 | R11: 13040 | S11: 1.2454 | T11: 1.1224 | U11: 107.53 | V11: 10470.53 | W11: 10504.82 | X11: =R11/T11 -> 11617.962 | Y11: 1.246
B12: 44018 | C12: 13242 | D12: 13242 | E12: =AVERAGE(C12:D12) -> 13242 | F12: 13308 | G12: 13308 | H12: =AVERAGE(F12:G12) -> 13308 | I12: 13572 | J12: 13572 | K12: =AVERAGE(I12:J12) -> 13572 | L12: 13794 | M12: 13794 | N12: =AVERAGE(L12:M12) -> 13794 | O12: 14024 | P12: 14024 | Q12: =AVERAGE(O12:P12) -> 14024 | R12: 13242 | S12: 1.251 | T12: 1.1319 | U12: 107.53 | V12: 10585.13 | W12: 10631.94 | X12: =R12/T12 -> 11698.913 | Y12: 1.2517
B13: 44019 | C13: 13231 | D13: 13231 | E13: =AVERAGE(C13:D13) -> 13231 | F13: 13286 | G13: 13286 | H13: =AVERAGE(F13:G13) -> 13286 | I13: 13552 | J13: 13552 | K13: =AVERAGE(I13:J13) -> 13552 | L13: 13774 | M13: 13774 | N13: =AVERAGE(L13:M13) -> 13774 | O13: 14004 | P13: 14004 | Q13: =AVERAGE(O13:P13) -> 14004 | R13: 13231 | S13: 1.2519 | T13: 1.1291 | U13: 107.72 | V13: 10568.74 | W13: 10606.74 | X13: =R13/T13 -> 11718.183 | Y13: 1.2526
B14: 44020 | C14: 13415 | D14: 13415 | E14: =AVERAGE(C14:D14) -> 13415 | F14: 13465 | G14: 13465 | H14: =AVERAGE(F14:G14) -> 13465 | I14: 13726 | J14: 13726 | K14: =AVERAGE(I14:J14) -> 13726 | L14: 13951 | M14: 13951 | N14: =AVERAGE(L14:M14) -> 13951 | O14: 14181 | P14: 14181 | Q14: =AVERAGE(O14:P14) -> 14181 | R14: 13415 | S14: 1.2559 | T14: 1.129 | U14: 107.52 | V14: 10681.58 | W14: 10715.42 | X14: =R14/T14 -> 11882.197 | Y14: 1.2566
B15: 44021 | C15: 13425 | D15: 13425 | E15: =AVERAGE(C15:D15) -> 13425 | F15: 13478 | G15: 13478 | H15: =AVERAGE(F15:G15) -> 13478 | I15: 13735 | J15: 13735 | K15: =AVERAGE(I15:J15) -> 13735 | L15: 13956 | M15: 13956 | N15: =AVERAGE(L15:M15) -> 13956 | O15: 14188 | P15: 14188 | Q15: =AVERAGE(O15:P15) -> 14188 | R15: 13425 | S15: 1.2652 | T15: 1.1343 | U15: 107.29 | V15: 10610.97 | W15: 10647.81 | X15: =R15/T15 -> 11835.493 | Y15: 1.2658
B16: 44022 | C16: 13070 | D16: 13070 | E16: =AVERAGE(C16:D16) -> 13070 | F16: 13108 | G16: 13108 | H16: =AVERAGE(F16:G16) -> 13108 | I16: 13367 | J16: 13367 | K16: =AVERAGE(I16:J16) -> 13367 | L16: 13588 | M16: 13588 | N16: =AVERAGE(L16:M16) -> 13588 | O16: 13818 | P16: 13818 | Q16: =AVERAGE(O16:P16) -> 13818 | R16: 13070 | S16: 1.2599 | T16: 1.1286 | U16: 106.86 | V16: 10373.84 | W16: 10398.22 | X16: =R16/T16 -> 11580.719 | Y16: 1.2606
B17: 44025 | C17: 13482 | D17: 13482 | E17: =AVERAGE(C17:D17) -> 13482 | F17: 13524 | G17: 13524 | H17: =AVERAGE(F17:G17) -> 13524 | I17: 13777 | J17: 13777 | K17: =AVERAGE(I17:J17) -> 13777 | L17: 13998 | M17: 13998 | N17: =AVERAGE(L17:M17) -> 13998 | O17: 14228 | P17: 14228 | Q17: =AVERAGE(O17:P17) -> 14228 | R17: 13482 | S17: 1.2604 | T17: 1.1335 | U17: 107.1 | V17: 10696.6 | W17: 10723.12 | X17: =R17/T17 -> 11894.133 | Y17: 1.2612
B18: 44026 | C18: 13518 | D18: 13518 | E18: =AVERAGE(C18:D18) -> 13518 | F18: 13567 | G18: 13567 | H18: =AVERAGE(F18:G18) -> 13567 | I18: 13811 | J18: 13811 | K18: =AVERAGE(I18:J18) -> 13811 | L18: 14026 | M18: 14026 | N18: =AVERAGE(L18:M18) -> 14026 | O18: 14256 | P18: 14256 | Q18: =AVERAGE(O18:P18) -> 14256 | R18: 13518 | S18: 1.253 | T18: 1.1378 | U18: 107.37 | V18: 10788.51 | W18: 10821.57 | X18: =R18/T18 -> 11880.823 | Y18: 1.2537
B19: 44027 | C19: 13512 | D19: 13512 | E19: =AVERAGE(C19:D19) -> 13512 | F19: 13555 | G19: 13555 | H19: =AVERAGE(F19:G19) -> 13555 | I19: 13798 | J19: 13798 | K19: =AVERAGE(I19:J19) -> 13798 | L19: 14018 | M19: 14018 | N19: =AVERAGE(L19:M19) -> 14018 | O19: 14248 | P19: 14248 | Q19: =AVERAGE(O19:P19) -> 14248 | R19: 13512 | S19: 1.2632 | T19: 1.1439 | U19: 106.9 | V19: 10696.64 | W19: 10724.74 | X19: =R19/T19 -> 11812.221 | Y19: 1.2639
B20: 44028 | C20: 13253 | D20: 13253 | E20: =AVERAGE(C20:D20) -> 13253 | F20: 13289 | G20: 13289 | H20: =AVERAGE(F20:G20) -> 13289 | I20: 13530 | J20: 13530 | K20: =AVERAGE(I20:J20) -> 13530 | L20: 13750 | M20: 13750 | N20: =AVERAGE(L20:M20) -> 13750 | O20: 13980 | P20: 13980 | Q20: =AVERAGE(O20:P20) -> 13980 | R20: 13253 | S20: 1.2555 | T20: 1.1413 | U20: 107.09 | V20: 10555.95 | W20: 10579.57 | X20: =R20/T20 -> 11612.197 | Y20: 1.2561
... B31: 44043 | C31: 13756 | D31: 13756 | E31: =AVERAGE(C31:D31) -> 13756 | F31: 13806 | G31: 13806 | H31: =AVERAGE(F31:G31) -> 13806 | I31: 14044 | J31: 14044 | K31: =AVERAGE(I31:J31) -> 14044 | L31: 14257 | M31: 14257 | N31: =AVERAGE(L31:M31) -> 14257 | O31: 14472 | P31: 14472 | Q31: =AVERAGE(O31:P31) -> 14472 | R31: 13756 | S31: 1.3142 | T31: 1.1841 | U31: 104.91 | V31: 10467.2 | W31: 10500.46 | X31: =R31/T31 -> 11617.262 | Y31: 1.3148
B32: Average | C32: =ROUND(AVERAGE(C9:C31),2) -> 13341.35 | D32: =ROUND(AVERAGE(D9:D31),2) -> 13341.35 | E32: =ROUND(AVERAGE(C32:D32),2) -> 13341.35 | F32: =ROUND(AVERAGE(F9:F31),2) -> 13388.83 | G32: =ROUND(AVERAGE(G9:G31),2) -> 13388.83 | H32: =ROUND(AVERAGE(F32:G32),2) -> 13388.83 | I32: =ROUND(AVERAGE(I9:I31),2) -> 13638.26 | J32: =ROUND(AVERAGE(J9:J31),2) -> 13638.26 | K32: =ROUND(AVERAGE(I32:J32),2) -> 13638.26 | L32: =ROUND(AVERAGE(L9:L31),2) -> 13856.91 | M32: =ROUND(AVERAGE(M9:M31),2) -> 13856.91 | N32: =ROUND(AVERAGE(L32:M32),2) -> 13856.91 | O32: =ROUND(AVERAGE(O9:O31),2) -> 14082.74 | P32: =ROUND(AVERAGE(P9:P31),2) -> 14082.74 | Q32: =ROUND(AVERAGE(O32:P32),2) -> 14082.74 | R32: =ROUND(AVERAGE(R9:R31),2) -> 13341.35 | S32: =ROUND(AVERAGE(S9:S31),4) -> 1.267 | T32: =ROUND(AVERAGE(T9:T31),4) -> 1.1462 | U32: =ROUND(AVERAGE(U9:U31),2) -> 106.77 | V32: =AVERAGE(V9:V31) -> 10529.799 | W32: =AVERAGE(W9:W31) -> 10561.807 | X32: =AVERAGE(X9:X31) -> 11639.515 | Y32: =AVERAGE(Y9:Y31) -> 1.2676261
B33: High | C33: =MAX(C9:C31) -> 13762 | D33: =MAX(D9:D31) -> 13762 | E33: =MAX(E9:E31) -> 13762 | F33: =MAX(F9:F31) -> 13809 | G33: =MAX(G9:G31) -> 13809 | H33: =MAX(H9:H31) -> 13809 | I33: =MAX(I9:I31) -> 14044 | J33: =MAX(J9:J31) -> 14044 | ... Y33: =MAX(Y9:Y31) -> 1.3148
B34: Low | C34: =MIN(C9:C31) -> 12555 | D34: =MIN(D9:D31) -> 12555 | E34: =MIN(E9:E31) -> 12555 | F34: =MIN(F9:F31) -> 12620 | G34: =MIN(G9:G31) -> 12620 | H34: =MIN(H9:H31) -> 12620 | I34: =MIN(I9:I31) -> 12895 | J34: =MIN(J9:J31) -> 12895 | ... Y34: =MIN(Y9:Y31) -> 1.2397
B36: Neither the LME nor any of its directors, officers or employees shall, except in the case of fraud or wilful neglect, be under any liability whatsoever either in
B37: contract or in tort in respect of any act or omission (including negligence) in relation to the preparation or publication of the data contained in the report

Sheet Cobalt
B3: LME DAILY OFFICIAL AND SETTLEMENT PRICES
B4: LME COBALT $USD/Tonne
B6: 44013
C7: CASH | F7: 3-MONTHS | I7: 15-MONTHS | L7: SETTLEMENT | M7: Exchange Rate | P7: Sterling Equivalents | R7: Euro Equivalents | S7: 3MStg/$
C8: BUYER | D8: SELLER | E8: Mean | F8: BUYER | G8: SELLER | H8: Mean | I8: BUYER | J8: SELLER | K8: Mean | M8: Stg/$ | N8: EURO | O8: Yen | P8: Cash Seller's | Q8: 3mths Seller's | R8: Cash Seller's | S8: 3MStg/$
B9: 44013 | C9: 28500 | D9: 28500 | E9: =AVERAGE(C9:D9) -> 28500 | F9: 28500 | G9: 28500 | H9: =AVERAGE(F9:G9) -> 28500 | I9: 30305 | J9: 30305 | K9: =AVERAGE(I9:J9) -> 30305 | L9: 28500 | M9: 1.239 | N9: 1.1204 | O9: 107.46 | P9: 23002.42 | Q9: 22989.43 | R9: =L9/N9 -> 25437.344 | S9: 1.2397
B10: 44014 | C10: 28500 | D10: 28500 | E10: =AVERAGE(C10:D10) -> 28500 | F10: 28500 | G10: 28500 | H10: =AVERAGE(F10:G10) -> 28500 | I10: 30300 | J10: 30300 | K10: =AVERAGE(I10:J10) -> 30300 | L10: 28500 | M10: 1.2519 | N10: 1.1287 | O10: 107.46 | P10: 22765.4 | Q10: 22752.67 | R10: =L10/N10 -> 25250.288 | S10: 1.2526
